## async/await基础用法

### await用法1

```js
function fn1 () {
	return 10;
}

(async function () {
	let value = await fn1()
  console.log(value);
  console.log('@@');
})()

console.log(1);
// 先输出 1
// 紧接着很快 输出 10 '@@'
```

#### 「await特点」

注意：即使`await`后面的函数是`普通函数`，也会默认把`fn1`看做是`promise`实例（只是为了类比返回的是成功态还是失败态，但并没有`then`方法）

- `await`处理后，立即把函数执行，哪怕函数立即返回成功或失败的状态，`await`后面的代码也没有立即执行，而是先等`fn1`函数同步的都执行完，再执行后面的代码（之前存储在微任务队列的`异步任务`）

### await用法2

```js
function fn2 () {
	return new Promise((resolve, reject) => {
		setTimeout(() => {
      resolve(2);
    }, 1000)
  })
}

(async function () {
	let value = await fn2()
  console.log(value);
  console.log('@@');
})()

console.log(1);
// 先输出 1
// 过1s 之后再输出 2 '@@'
```

#### 「await特点」

- `await`关键字需要与`async`关键字连用

- `await`后面的函数如果返回的是`promise`实例的话，可以通过`await fn2().then`拿到成功后的值

  ```js
  let value2 = await fn2().then(data => console.log(data)); // 2
  ```

- `await`函数执行时（分两步执行）

  - 先把await后面的函数执行（fn2），观察fn2返回的是成功的promise还是失败的promise
  - 紧接着它会把当前上下文中，await后面的代码整体都当作一个异步的微任务，放置在`EventQueue`

- `await`只能处理`promise`实例是成功状态的函数
  - 如果返回状态是成功（resolve），则上述value取得的是`PromiseValue`，并且把之前存储的异步任务拿到栈中让主线程执行
  - 如果返回状态是失败（rejected），则直接报错，应该用`try/catch捕获`

### await用法3

```js
function fn3 () {
	return new Promise((resolve, reject) => {
		setTimeout(() => {
			reject(3);
    }, 1000)
  })
}

(async function () {
  try {
    let value2 = await fn3()
    console.log(value);
    console.log('@@');
  } catch (e) {
    console.log(e)
  }
})()

console.log(1);
// 1
// 3
```

对于`await`处理函数的时候，如果返回的是失败的`promise`，则`await`后面代码不再执行，失败情况下没有处理，浏览器抛出一个异常信息。

此时我们可以基于`try/catch`捕获异常，从而进行异常的处理，让浏览器不再报错。
